Workbook

Sheet Raw_Dataset
A1: Crop | B1: Crop_Year | C1: Season | D1: State | E1: Area | F1: Production | G1: Annual_Rainfall | H1: Fertilizer | I1: Pesticide | J1: Yield | K1: Avg_Temperature | L1: Max_Temperature | M1: Min_Temperature
A2: Rice | B2: 1997 | C2: Autumn | D2: Assam | E2: 607358 | F2: 398311 | G2: 2051.4 | H2: 57802261 | I2: 188280.98 | J2: 0.781 | K2: 23.692 | L2: 33.435 | M2: 14.779
A3: Rice | B3: 1997 | C3: Summer | D3: Assam | F3: 209623 | G3: 2051.4 | H3: 16652276 | J3: 1.06 | K3: 23.692 | L3: 33.435 | M3: 14.779
A4: Rice | B4: 1997 | C4: Winter | D4: Assam | E4: 1743321 | F4: 1647296 | G4: 2051.4 | H4: 1.6591186e+08 | I4: 540429.51 | J4: 0.941 | K4: 23.692 | L4: 33.435 | M4: 14.779
A5: Sugarcane | B5: 1997 | C5: Kharif | D5: Assam | E5: 31318 | F5: 1287451 | G5: 2051.4 | I5: 9708.58 | J5: 41.897 | K5: 23.692 | L5: 33.435 | M5: 14.779
A6: Wheat | B6: 1997 | C6: Rabi | D6: Assam | E6: 84698 | F6: 110054 | G6: 2051.4 | H6: 8060708.7 | I6: 26256.38 | J6: 1.26 | K6: 23.692 | L6: 33.435 | M6: 14.779
A7: Ragi | B7: 1997 | C7: Kharif | D7: Karnataka | E7: 897921 | F7: 1214282 | G7: 1266.7 | H7: 85455142 | I7: 278355.51 | J7: 1.191 | K7: 25.766 | L7: 35.922 | M7: 16.838
A8: Ragi | B8: 1997 | D8: Karnataka | E8: 27104 | F8: 33696 | G8: 1266.7 | H8: 2579487.7 | I8: 8402.24 | J8: 1.312 | K8: 25.766 | L8: 35.922 | M8: 16.838
A9: Ragi | B9: 1997 | C9: Summer | D9: Karnataka | E9: 13521 | F9: 25035 | G9: 1266.7 | H9: 1286793.6 | I9: 4191.51 | J9: 1.848 | K9: 25.766 | L9: 35.922 | M9: 16.838
A10: Rice | B10: 1997 | C10: Kharif | D10: Karnataka | E10: 1031530 | F10: 2340493 | G10: 1266.7 | H10: 98170710 | I10: 319774.3 | J10: 2.234 | K10: 25.766 | L10: 35.922 | M10: 16.838
A11: Rice | B11: 1997 | C11: Rabi | D11: Karnataka | E11: 53889 | F11: 109350 | G11: 1266.7 | H11: 5128616.1 | I11: 16705.59 | K11: 25.766 | L11: 35.922 | M11: 16.838
A12: Rice | B12: 1997 | C12: Summer | D12: Karnataka | E12: 268044 | F12: 762759 | G12: 1266.7 | H12: 25509747 | I12: 83093.64 | J12: 2.829 | K12: 25.766 | L12: 35.922 | M12: 16.838
A13: Sugarcane | B13: 1997 | C13: Whole Year | D13: Karnataka | E13: 308857 | F13: 28999269 | G13: 1266.7 | I13: 95745.67 | J13: 91.747 | K13: 25.766 | L13: 35.922 | M13: 16.838
A14: Wheat | B14: 1997 | C14: Rabi | D14: Karnataka | E14: 250698 | F14: 118512 | G14: 1266.7 mm | H14: 23858929 | I14: 77716.38 | J14: 0.548 | K14: 25.766 | L14: 35.922 | M14: 16.838
A15: Rice | B15: 1997 | C15: Kharif | D15: Meghalaya | E15: 105170 | F15: 150101 | G15: 3818.2 | I15: 32602.7 | J15: 1.379 | K15: 18.57 | L15: 26.645 | M15: 10.664
A16: Sugarcane | B16: 1997 | C16: Whole Year | D16: Meghalaya | E16: 82 | F16: 225 | G16: 3818.2 | H16: 7803.94 | I16: 25.42 | J16: 2.352 | K16: 18.57 | L16: 26.645 | M16: 10.664
A17: Wheat | B17: 1997 | C17: Rabi | D17: Meghalaya | E17: 4287 | F17: 6894 | G17: 3818.2 | H17: 407993.79 | I17: 1328.97 | J17: 1.385 | K17: 18.57 | L17: 26.645 | M17: 10.664
A18: Ragi | B18: 1997 | C18: Autumn | D18: West Bengal | E18: 12607 | F18: 15330 | G18: 1852.9 | H18: 1199808.2 | I18: 3908.17 | J18: 0.986 | K18: 25.795 | L18: 35.236 | M18: 17.038
A19: Rice | B19: 1997 | C19: Autumn | D19: West Bengal | E19: 423121 | F19: 751,970 | G19: 1852.9 | H19: 40268426 | J19: 1.837 | K19: 25.795 | L19: 35.236 | M19: 17.038
A20: Rice | B20: 1997 | C20: Summer | D20: West Bengal | E20: 1206829 | F20: 3569520 | G20: 1852.9 | H20: 1.1485392e+08 | I20: 374116.99 kg | J20: 2.844 | K20: 25.795 | L20: 35.236 | M20: 17.038
A21: Rice | B21: 1997 | C21: Winter | D21: West Bengal | E21: 4270328 | F21: 8915100 | G21: 18529 | H21: 4.0640712e+08 | I21: 1323801.7 | J21: 1.986 | K21: 25.795 | L21: 35.236 | M21: 17.038
A22: Sugarcane | B22: 1997 | C22: Whole Year | D22: West Bengal | E22: 25797 | F22: 1818700 | G22: 1852.9 | H22: 2455100.5 | I22: 7997.07 | J22: 67.836 | K22: 25.795 | L22: 35.236 | M22: 17.038
A23: Sunflower | B23: 1997 | C23: Whole Year | D23: West Bengal | E23: 278 | F23: 1 | I23: 86.18 | K23: 25.795 | L23: 35.236 | M23: 17.038
A24: Urad | B24: 1997 | C24: kharif | D24: West Bengal | E24: 69271 | F24: 44480 | G24: 1852.9 | H24: 6592521.1 | I24: 21474.01 | J24: 1.825 | K24: 25.795 | L24: 35.236 | M24: 17.038
A25: Urad | B25: 1997 | C25: rabi | D25: West Bengal | E25: 16694 | F25: 10553 | G25: 1852.9 | H25: 1588768 | I25: 5175.14 | J25: 0.628 | K25: 25.795 | L25: 35.236 | M25: 17.038
A26: Wheat | B26: 1997 | C26: Rabi | D26: West Bengal | E26: 367374 | G26: 1852.9 | H26: 34962984 | I26: 113885.94 | J26: 1.887 | K26: 25.795 | L26: 35.236 | M26: 17.038
A27: Ragi | B27: 1998 | C27: Kharif | D27: Puducherry | E27: 112 | F27: 366 | G27: 1434.588 | H27: 11065.6 | I27: 32.48 | J27: 3.27 | K27: 28.324 | L27: 32.859 | M27: 24.576
A28: Rice | B28: 1998 | C28: Kharif | D28: Puducherry | E28: 4945 | F28: 11518 | G28: 1434.588 | H28: 488566 | I28: 1434.05 | J28: 2.46 | K28: 28.324 | L28: 32.859 | M28: 24.576
A29: Rice | B29: 1998 | D29: Puducherry | E29: 13961 | F29: 30220 | G29: 1434.588 | H29: 1379346.8 | I29: 4048.69 | J29: 2.555 | K29: 28.324 | L29: 32.859 | M29: 24.576
A30: Rice | B30: 1998 | C30: Summer | D30: Puducherry | E30: 5716 | F30: 14863 | G30: 1434.588 | H30: 564740.8 | I30: 1657.64 | J30: 2.55 | K30: 28.324 | L30: 32.859 | M30: 24.576
A31: Sugarcane | B31: 1998 | C31: Kharif | D31: Puducherry | E31: 2710 | F31: 232369 | G31: 1434.588 | H31: 267748 | I31: 785.9 | J31: 82.595 | K31: 28.324 | L31: 32.859 | M31: 24.576
A32: Rice | B32: 1998 | C32: Autumn | D32: Assam | E32: 594979 | F32: 520605 | G32: 2354.4 | H32: 58783925 | I32: 172543.91 | J32: 1.056 | K32: 24.142 | L32: 33.323 | M32: 16.002
A33: Rice | B33: 1998 | C33: Summer | D33: Assam | E33: 223913 | F33: 446114 | G33: 2354.4 | H33: 22122604 | I33: 64934.77 | J33: 1.685 | K33: 24.142 | L33: 33.323 | M33: 16.002
A34: Rice | B34: 1998 | C34: Winter | D34: Assam | E34: 1635230 | F34: 2288114 | G34: 2354.4 | H34: 161560724 | I34: 474216.7 | J34: 1.396 | K34: 24.142 | L34: 33.323 | M34: 16.002
A35: Sugarcane | B35: 1998 | C35: Whole Year | D35: Assam | E35: 30571 | F35: 1223578 | G35: 2354.4 | H35: 3020414.8 | I35: 8865.59 | J35: 39.893 | K35: 24.142 | L35: 33.323 | M35: 16.002
A36: Wheat | B36: 1998 | C36: Rabi | D36: Assam | E36: 89591 | F36: 90509 | G36: 2354.4 | H36: 8851590.8 | I36: 25981.39 | J36: 1 | K36: 24.142 | L36: 33.323 | M36: 16.002
A37: Ragi | B37: 1998 | C37: Kharif | D37: Goa | F37: 2476 | G37: 2964.9 | H37: 247000 | I37: 725 | J37: 0.99 | K37: 25.083 | L37: 34.938 | M37: 17.258
A38: Rice | B38: 1998 | C38: KHARIF | D38: Goa | E38: 41000 | F38: 104249 | G38: 2964.9 | H38: 4050800 | I38: 11890 | J38: 2.54 | K38: 25.083 | L38: 34.938 | M38: 17.258
A39: Rice | B39: 1998 | C39: RABI | D39: Goa | E39: 15439 | F39: 46925 | G39: 2964.9 | H39: 1525373.2 | I39: 4477.31 | J39: 3.04 | K39: 25.083 | L39: 34.938 | M39: 17.258
A40: Sugarcane | B40: 1998 | C40: Whole Year | D40: Goa | E40: 1320 | F40: 64000 | G40: 2964.9 | H40: 130416 | I40: 382.8 | J40: 48.48 | K40: 25.083 | L40: 34.938 | M40: 17.258
...

Sheet 2010-2020crops cleaned
A1: Crop | B1: Crop_Year | C1: Season | D1: State | E1: Area(hectare) | F1: Production(Tones) | G1: Calculated Production | H1: Annual_Rainfall(mm) | I1: Fertilizer(kg) | J1: Pesticide(kg) | K1: Yield | L1: Avg_Temperature(°C) | M1: Max_Temperature(°C) | N1: Min_Temperature(°C)
A2: Ragi | B2: 2010 | C2: Kharif | D2: Puducherry | E2: 14 | F2: 29 | G2: 22.05 | H2: 1434.588 | I2: 2325.54 | J2: 3.36 | K2: 1.575 | L2: 28.059 | M2: 32.519 | N2: 24.308
A3: Ragi | B3: 2010 | C3: Rabi | D3: Puducherry | E3: 1 | F3: 2 | G3: 2 | H3: 1434.588 | I3: 166.11 | J3: 0.24 | K3: 2 | L3: 28.059 | M3: 32.519 | N3: 24.308
A4: Ragi | B4: 2010 | C4: Summer | D4: Puducherry | E4: 8 | F4: 20 | G4: 20 | H4: 1434.588 | I4: 1328.88 | J4: 1.92 | K4: 2.5 | L4: 28.059 | M4: 32.519 | N4: 24.308
A5: Rice | B5: 2010 | C5: Kharif | D5: Puducherry | E5: 4384 | F5: 12602 | G5: 11718.432 | H5: 1434.588 | I5: 728226.24 | J5: 1052.16 | K5: 2.673 | L5: 28.059 | M5: 32.519 | N5: 24.308
A6: Rice | B6: 2010 | C6: Rabi | D6: Puducherry | E6: 10920 | F6: 26585 | G6: 37641.24 | H6: 1434.588 | I6: 1813921.2 | J6: 2620.8 | K6: 3.447 | L6: 28.059 | M6: 32.519 | N6: 24.308
A7: Rice | B7: 2010 | C7: Summer | D7: Puducherry | E7: 4710 | F7: 12773 | G7: 12717 | H7: 1434.588 | I7: 782378.1 | J7: 1130.4 | K7: 2.7 | L7: 28.059 | M7: 32.519 | N7: 24.308
A8: Sugarcane | B8: 2010 | C8: Kharif | D8: Puducherry | E8: 1765 | F8: 277683 | G8: 203310.35 | H8: 1434.588 | I8: 293184.15 | J8: 423.6 | K8: 115.19 | L8: 28.059 | M8: 32.519 | N8: 24.308
A9: Sunflower | B9: 2010 | C9: Kharif | D9: Puducherry | E9: 1 | F9: 1 | G9: 1 | H9: 1434.588 | I9: 166.11 | J9: 0.24 | K9: 1 | L9: 28.059 | M9: 32.519 | N9: 24.308
A10: Urad | B10: 2010 | C10: Kharif | D10: Puducherry | E10: 22 | F10: 17 | G10: 16.94 | H10: 1434.588 | I10: 3654.42 | J10: 5.28 | K10: 0.77 | L10: 28.059 | M10: 32.519 | N10: 24.308
A11: Urad | B11: 2010 | C11: Rabi | D11: Puducherry | E11: 189 | F11: 206 | G11: 206.01 | H11: 1434.588 | I11: 31394.79 | J11: 45.36 | K11: 1.09 | L11: 28.059 | M11: 32.519 | N11: 24.308
A12: Urad | B12: 2010 | C12: Summer | D12: Puducherry | E12: 916 | F12: 374 | G12: 574.332 | H12: 1434.588 | I12: 152156.76 | J12: 219.84 | K12: 0.627 | L12: 28.059 | M12: 32.519 | N12: 24.308
A13: Rice | B13: 2010 | C13: Autumn | D13: Assam | E13: 307988 | F13: 355825 | G13: 392068.72 | H13: 2578.5 | I13: 51159887 | J13: 73917.12 | K13: 1.273 | L13: 23.876 | M13: 32.111 | N13: 16.375
... A31: Rice | B31: 2010 | C31: Kharif | D31: Karnataka | E31: 1129304 | F31: 2997172.8 | G31: 2997172.8 | H31: 1317.7 | I31: 1.8758869e+08 | J31: 139190.19 | K31: 2.654 | L31: 25.658 | M31: 35.068 | N31: 16.714
A32: Rice | B32: 2010 | C32: Rabi | D32: Karnataka | E32: 49700 | F32: 117501 | G32: 1325996 | H32: 1317.7 | I32: 8255667 | J32: 11928 | K32: 26.68 | L32: 25.658 | M32: 35.07 | N32: 16.714
A33: Rice | B33: 2010 | C33: Summer | D33: Karnataka | E33: 360062 | F33: 1163725 | G33: 1057142 | H33: 1317.7 | I33: 59809899 | J33: 86414.88 | K33: 2.936 | L33: 25.658 | M33: 35.670389 | N33: 16.714
A34: Sugarcane | B34: 2010 | C34: Whole Year | D34: Karnataka | E34: 436798 | F34: 42276713 | G34: 42513986 | H34: 1317.7 | I34: 72556516 | J34: 104831.52 | K34: 97.331 | L34: 25.658 | M34: 35.068 | N34: 16.714
A35: Sunflower | B35: 2010 | C35: Kharif | D35: Karnataka | E35: 193955 | F35: 97869 | G35: 110554.35 | H35: 1317.7 | I35: 32217865 | J35: 46549.2 | K35: 0.57 | L35: 25.658 | M35: 35.068 | N35: 16.714
A36: Sunflower | B36: 2010 | C36: Rabi | D36: Karnataka | E36: 193178 | F36: 98783 | G36: 136576.85 | H36: 1317.7 | I36: 32088798 | J36: 46362.72 | K36: 0.707 | L36: 25.658 | M36: 35.068 | N36: 16.714
A37: Sunflower | B37: 2010 | C37: Summer | D37: Karnataka | E37: 22120 | F37: 22405 | G37: 22827.84 | H37: 1317.7 | I37: 3674353.2 | J37: 5308.8 | K37: 1.032 | L37: 25.658 | M37: 35.068 | N37: 16.714
A38: Urad | B38: 2010 | C38: Kharif | D38: Karnataka | E38: 118318 | F38: 42990 | G38: 42949.434 | H38: 1317.7 | I38: 19653803 | J38: 28396.32 | K38: 0.363 | L38: 25.891 | M38: 35.068 | N38: 16.714
A39: Urad | B39: 2010 | C39: Rabi | D39: Karnataka | E39: 8727 | F39: 4079 | G39: 4079 | H39: 1317.7 | I39: 1449642 | J39: 2094.48 | K39: 0.46740002 | L39: 25.658 | M39: 35.068 | N39: 16.661878
A40: Wheat | B40: 2010 | C40: Rabi | D40: Karnataka | E40: 254755 | F40: 300237 | G40: 297044.33 | H40: 1317.7 | I40: 42317353 | J40: 63845.544 | K40: 1.166 | L40: 25.658 | M40: 35.068 | N40: 16.714
A41: Rice | B41: 2010 | C41: Autumn | D41: Kerala | E41: 70498.28 | F41: 170262 | G41: 157704.65 | H41: 3131.8 | I41: 11710469 | J41: 16919.587 | K41: 2.237 | L41: 25.239 | M41: 32.523 | N41: 20.003
A42: Rice | B42: 2010 | C42: Summer | D42: Kerala | E42: 51132.63 | F42: 137465 | G42: 126808.92 | H42: 3131.8 | I42: 8493641.2 | J42: 12271.831 | K42: 2.48 | L42: 25.239 | M42: 32.523 | N42: 20.003
A43: Rice | B43: 2010 | C43: Winter | D43: Kerala | E43: 91555.59 | F43: 215011 | G43: 201605.41 | H43: 3131.8 | I43: 15208299 | J43: 21973.342 | K43: 2.202 | L43: 25.239 | M43: 32.523 | N43: 20.003
A44: Sugarcane | B44: 2010 | C44: Whole Year | D44: Kerala | E44: 2844.91 | F44: 271845 | G44: 118112.13 | H44: 3131.8 | I44: 472568 | J44: 682.778 | K44: 41.517 | L44: 25.239 | M44: 32.523 | N44: 20.003
A45: Rice | B45: 2010 | C45: Autumn | D45: Meghalaya | E45: 32596 | F45: 42492 | G45: 49871.88 | H45: 3119.7 | I45: 5414521.6 | J45: 7823.04 | K45: 1.53 | L45: 19.235 | M45: 26.452 | N45: 11.877
A46: Rice | B46: 2010 | C46: Rabi | D46: Meghalaya | E46: 12797 | F46: 47413 | G46: 26579.369 | H46: 3119.7 | I46: 2125709.7 | J46: 3071.28 | K46: 2.077 | L46: 19.235 | M46: 26.452 | N46: 11.877
A47: Rice | B47: 2010 | C47: Winter | D47: Meghalaya | E47: 62892 | F47: 117116 | G47: 115029.47 | H47: 3119.7 | I47: 10446990 | J47: 15094.08 | K47: 1.829 | L47: 19.235 | M47: 26.452 | N47: 11.877
A48: Sugarcane | B48: 2010 | C48: Whole Year | D48: Meghalaya | E48: 68 | F48: 180 | G48: 159.8 | H48: 3119.7 | I48: 11295.48 | J48: 16.32 | K48: 2.35 | L48: 19.235 | M48: 26.452 | N48: 11.877
A49: Wheat | B49: 2010 | C49: Rabi | D49: Meghalaya | E49: 393 | F49: 704 | G49: 490.464 | H49: 3119.7 | I49: 65281.23 | J49: 94.32 | K49: 1.248 | L49: 19.235 | M49: 26.452 | N49: 11.877
A50: Ragi | B50: 2011 | C50: Kharif | D50: Puducherry | E50: 12 | F50: 33 | G50: 33 | H50: 1434.588 | I50: 2010.24 | J50: 3.96 | K50: 2.75 | L50: 27.938 | M50: 32.262 | N50: 24.39863
A51: Ragi | B51: 2011 | C51: Summer | D51: Puducherry | E51: 10 | F51: 25 | G51: 25 | H51: 1434.588 | I51: 1675.2 | J51: 3.3 | K51: 2.5 | L51: 27.938 | M51: 32.262 | N51: 24.39863
A52: Rice | B52: 2011 | C52: Kharif | D52: Puducherry | E52: 4237 | F52: 12794 | G52: 12910.139 | H52: 1434.588 | I52: 709782.24 | J52: 1398.21 | K52: 3.047 | L52: 27.938 | M52: 32.262 | N52: 23.946
A53: Rice | B53: 2011 | C53: Rabi | D53: Puducherry | E53: 10324 | F53: 23489 | G53: 29495.668 | H53: 1434.588 | I53: 1729476.5 | J53: 3406.92 | K53: 2.857 | L53: 27.938 | M53: 32.262 | N53: 23.946
A54: Rice | B54: 2011 | C54: Kharif | D54: Puducherry | E54: 2015 | F54: 5831 | G54: 5017.35 | H54: 1434.588 | I54: 337552.8 | J54: 664.95 | K54: 2.49 | L54: 27.938 | M54: 32.262 | N54: 23.946
A55: Sugarcane | B55: 2011 | C55: Kharif | D55: Puducherry | E55: 1949 | F55: 287785 | G55: 287789.34 | H55: 1434.588 | I55: 326496.48 | J55: 643.17 | K55: 147.66 | L55: 27.938 | M55: 32.262 | N55: 24.39863
A56: Urad | B56: 2011 | C56: Kharif | D56: Puducherry | E56: 15 | F56: 12 | G56: 12 | H56: 1434.588 | I56: 2512.8 | J56: 4.95 | K56: 0.8 | L56: 27.938 | M56: 32.262 | N56: 23.946
A57: Urad | B57: 2011 | C57: Rabi | D57: Puducherry | E57: 224 | F57: 242 | G57: 185.92 | H57: 1434.588 | I57: 37524.48 | J57: 73.92 | K57: 0.83 | L57: 27.938 | M57: 32.711189 | N57: 23.946
...

Sheet 2010-2020crops
A1: Crop | B1: Crop_Year | C1: Season | D1: proper &trim | E1: blanks in season | F1: State | G1: Area(hectare) | H1: Area Blanks | I1: Production(Tones) | J1: Production blanks | K1: Annual_Rainfall(mm) | L1: Rainfall blanks | M1: crop&state | N1: Fertilizer(kg) | O1: Fertilizer Blanks | P1: Pesticide(kg) | Q1: Pesticide blanks | R1: Yield | S1: Yield blanks | T1: Avg_Temperature(°C) | U1: avg temp blanks | V1: Max_Temperature(°C) | W1: max temp blanks | X1: Min_Temperature(°C) | Y1: min temp blanks
A2: Ragi | B2: 2010 | C2: Kharif | D2: =PROPER(TRIM(Table2[[#This Row],[Season]])) -> Kharif | E2: =IF(Table2[[#This Row],[Season]]="",_xlfn.XLOOKUP(Table2[[#This Row],[State]],'pivot tables'!$F$3:$F$33,'pivot tables'!$G$3:$G$33),Table2[[#This Row],[Season]]) -> Kharif | F2: Puducherry | G2: 14 | H2: =IF(Table2[[#This Row],[Area(hectare)]]="",IFERROR(Table2[[#This Row],[Production(Tones)]]/Table2[[#This Row],[Yield blanks]],""),Table2[[#This Row],[Area(hectare)]]) -> 14 | I2: 29 | J2: =IF(Table2[[#This Row],[Production(Tones)]]="",Table2[[#This Row],[Area Blanks]]*Table2[[#This Row],[Yield]],Table2[[#This Row],[Production(Tones)]]) -> 29 | K2: 1434.588 | L2: =IF(Table2[[#This Row],[Annual_Rainfall(mm)]]="",_xlfn.XLOOKUP(Table2[[#This Row],[State]],'pivot tables'!$J$3:$J$32,'pivot tables'!$K$3:$K$32),Table2[[#This Row],[Annual_Rainfall(mm)]]) -> 1434.588 | M2: =Table2[[#This Row],[Crop]]&Table2[[#This Row],[State]] -> RagiPuducherry | N2: 2325.54 | O2: =IF(Table2[[#This Row],[Fertilizer(kg)]]="",_xlfn.XLOOKUP(Table2[[#This Row],[crop&state]],'pivot tables'!$O$3:$O$151,'pivot tables'!$P$3:$P$151),Table2[[#This Row],[Fertilizer(kg)]]) -> 2325.54 | P2: 3.36 | Q2: =IF(Table2[[#This Row],[Pesticide(kg)]]="",_xlfn.XLOOKUP(Table2[[#This Row],[crop&state]],'pivot tables'!$O$3:$O$151,'pivot tables'!$Q$3:$Q$151),Table2[[#This Row],[Pesticide(kg)]]) -> 3.36 | R2: 1.575 | S2: =IF(Table2[[#This Row],[Yield]]="",IFERROR(Table2[[#This Row],[Production(Tones)]]/Table2[[#This Row],[Area(hectare)]],""),Table2[[#This Row],[Yield]]) -> 1.575 | T2: 28.059 | U2: =IF(Table2[[#This Row],[Avg_Temperature(°C)]]="",IFERROR((Table2[[#This Row],[Max_Temperature(°C)]]+Table2[[#This Row],[Min_Temperature(°C)]])/2,""),Table2[[#This Row],[Avg_Temperature(°C)]]) -> 28.059 | V2: 32.519 | W2: =IF(Table2[[#This Row],[Max_Temperature(°C)]]="",_xlfn.XLOOKUP(Table2[[#This Row],[State]],'pivot tables'!$T$2:$T$33,'pivot tables'!$V$2:$V$33),Table2[[#This Row],[Max_Temperature(°C)]]) -> 32.519 | X2: 24.308 | Y2: =IF(Table2[[#This Row],[Min_Temperature(°C)]]="",_xlfn.XLOOKUP(Table2[[#This Row],[State]],'pivot tables'!$T$2:$T$33,'pivot tables'!$W$2:$W$33),Table2[[#This Row],[Min_Temperature(°C)]]) -> 24.308
A3: Ragi | B3: 2010 | C3: Rabi | D3: =PROPER(TRIM(Table2[[#This Row],[Season]])) -> Rabi | E3: =IF(Table2[[#This Row],[Season]]="",_xlfn.XLOOKUP(Table2[[#This Row],[State]],'pivot tables'!$F$3:$F$33,'pivot tables'!$G$3:$G$33),Table2[[#This Row],[Season]]) -> Rabi | F3: Puducherry | G3: 1 | H3: =IF(Table2[[#This Row],[Area(hectare)]]="",IFERROR(Table2[[#This Row],[Production(Tones)]]/Table2[[#This Row],[Yield blanks]],""),Table2[[#This Row],[Area(hectare)]]) -> 1 | I3: 2 | J3: =IF(Table2[[#This Row],[Production(Tones)]]="",Table2[[#This Row],[Area Blanks]]*Table2[[#This Row],[Yield]],Table2[[#This Row],[Production(Tones)]]) -> 2 | K3: 1434.588 | L3: =IF(Table2[[#This Row],[Annual_Rainfall(mm)]]="",_xlfn.XLOOKUP(Table2[[#This Row],[State]],'pivot tables'!$J$3:$J$32,'pivot tables'!$K$3:$K$32),Table2[[#This Row],[Annual_Rainfall(mm)]]) -> 1434.588 | M3: =Table2[[#This Row],[Crop]]&Table2[[#This Row],[State]] -> RagiPuducherry | N3: 166.11 | O3: =IF(Table2[[#This Row],[Fertilizer(kg)]]="",_xlfn.XLOOKUP(Table2[[#This Row],[crop&state]],'pivot tables'!$O$3:$O$151,'pivot tables'!$P$3:$P$151),Table2[[#This Row],[Fertilizer(kg)]]) -> 166.11 | P3: 0.24 | Q3: =IF(Table2[[#This Row],[Pesticide(kg)]]="",_xlfn.XLOOKUP(Table2[[#This Row],[crop&state]],'pivot tables'!$O$3:$O$151,'pivot tables'!$Q$3:$Q$151),Table2[[#This Row],[Pesticide(kg)]]) -> 0.24 | S3: =IF(Table2[[#This Row],[Yield]]="",IFERROR(Table2[[#This Row],[Production(Tones)]]/Table2[[#This Row],[Area(hectare)]],""),Table2[[#This Row],[Yield]]) -> 2 | T3: 28.059 | U3: =IF(Table2[[#This Row],[Avg_Temperature(°C)]]="",IFERROR((Table2[[#This Row],[Max_Temperature(°C)]]+Table2[[#This Row],[Min_Temperature(°C)]])/2,""),Table2[[#This Row],[Avg_Temperature(°C)]]) -> 28.059 | V3: 32.519 | W3: =IF(Table2[[#This Row],[Max_Temperature(°C)]]="",_xlfn.XLOOKUP(Table2[[#This Row],[State]],'pivot tables'!$T$2:$T$33,'pivot tables'!$V$2:$V$33),Table2[[#This Row],[Max_Temperature(°C)]]) -> 32.519 | X3: 24.308 | Y3: =IF(Table2[[#This Row],[Min_Temperature(°C)]]="",_xlfn.XLOOKUP(Table2[[#This Row],[State]],'pivot tables'!$T$2:$T$33,'pivot tables'!$W$2:$W$33),Table2[[#This Row],[Min_Temperature(°C)]]) -> 24.308
A4: Ragi | B4: 2010 | C4: Summer | D4: =PROPER(TRIM(Table2[[#This Row],[Season]])) -> Summer | E4: =IF(Table2[[#This Row],[Season]]="",_xlfn.XLOOKUP(Table2[[#This Row],[State]],'pivot tables'!$F$3:$F$33,'pivot tables'!$G$3:$G$33),Table2[[#This Row],[Season]]) -> Summer | F4: Puducherry | G4: 8 | H4: =IF(Table2[[#This Row],[Area(hectare)]]="",IFERROR(Table2[[#This Row],[Production(Tones)]]/Table2[[#This Row],[Yield blanks]],""),Table2[[#This Row],[Area(hectare)]]) -> 8 | I4: 20 | J4: =IF(Table2[[#This Row],[Production(Tones)]]="",Table2[[#This Row],[Area Blanks]]*Table2[[#This Row],[Yield]],Table2[[#This Row],[Production(Tones)]]) -> 20 | K4: 1434.588 | L4: =IF(Table2[[#This Row],[Annual_Rainfall(mm)]]="",_xlfn.XLOOKUP(Table2[[#This Row],[State]],'pivot tables'!$J$3:$J$32,'pivot tables'!$K$3:$K$32),Table2[[#This Row],[Annual_Rainfall(mm)]]) -> 1434.588 | M4: =Table2[[#This Row],[Crop]]&Table2[[#This Row],[State]] -> RagiPuducherry | N4: 1328.88 | O4: =IF(Table2[[#This Row],[Fertilizer(kg)]]="",_xlfn.XLOOKUP(Table2[[#This Row],[crop&state]],'pivot tables'!$O$3:$O$151,'pivot tables'!$P$3:$P$151),Table2[[#This Row],[Fertilizer(kg)]]) -> 1328.88 | P4: 1.92 | Q4: =IF(Table2[[#This Row],[Pesticide(kg)]]="",_xlfn.XLOOKUP(Table2[[#This Row],[crop&state]],'pivot tables'!$O$3:$O$151,'pivot tables'!$Q$3:$Q$151),Table2[[#This Row],[Pesticide(kg)]]) -> 1.92 | R4: 2.5 | S4: =IF(Table2[[#This Row],[Yield]]="",IFERROR(Table2[[#This Row],[Production(Tones)]]/Table2[[#This Row],[Area(hectare)]],""),Table2[[#This Row],[Yield]]) -> 2.5 | T4: 28.059 | U4: =IF(Table2[[#This Row],[Avg_Temperature(°C)]]="",IFERROR((Table2[[#This Row],[Max_Temperature(°C)]]+Table2[[#This Row],[Min_Temperature(°C)]])/2,""),Table2[[#This Row],[Avg_Temperature(°C)]]) -> 28.059 | V4: 32.519 | W4: =IF(Table2[[#This Row],[Max_Temperature(°C)]]="",_xlfn.XLOOKUP(Table2[[#This Row],[State]],'pivot tables'!$T$2:$T$33,'pivot tables'!$V$2:$V$33),Table2[[#This Row],[Max_Temperature(°C)]]) -> 32.519 | X4: 24.308 | Y4: =IF(Table2[[#This Row],[Min_Temperature(°C)]]="",_xlfn.XLOOKUP(Table2[[#This Row],[State]],'pivot tables'!$T$2:$T$33,'pivot tables'!$W$2:$W$33),Table2[[#This Row],[Min_Temperature(°C)]]) -> 24.308
A5: Rice | B5: 2010 | C5: Kharif | D5: =PROPER(TRIM(Table2[[#This Row],[Season]])) -> Kharif | E5: =IF(Table2[[#This Row],[Season]]="",_xlfn.XLOOKUP(Table2[[#This Row],[State]],'pivot tables'!$F$3:$F$33,'pivot tables'!$G$3:$G$33),Table2[[#This Row],[Season]]) -> Kharif | F5: Puducherry | G5: 4384 | H5: =IF(Table2[[#This Row],[Area(hectare)]]="",IFERROR(Table2[[#This Row],[Production(Tones)]]/Table2[[#This Row],[Yield blanks]],""),Table2[[#This Row],[Area(hectare)]]) -> 4384 | I5: 12602 | J5: =IF(Table2[[#This Row],[Production(Tones)]]="",Table2[[#This Row],[Area Blanks]]*Table2[[#This Row],[Yield]],Table2[[#This Row],[Production(Tones)]]) -> 12602 | K5: 1434.588 | L5: =IF(Table2[[#This Row],[Annual_Rainfall(mm)]]="",_xlfn.XLOOKUP(Table2[[#This Row],[State]],'pivot tables'!$J$3:$J$32,'pivot tables'!$K$3:$K$32),Table2[[#This Row],[Annual_Rainfall(mm)]]) -> 1434.588 | M5: =Table2[[#This Row],[Crop]]&Table2[[#This Row],[State]] -> RicePuducherry | N5: 728226.24 | O5: =IF(Table2[[#This Row],[Fertilizer(kg)]]="",_xlfn.XLOOKUP(Table2[[#This Row],[crop&state]],'pivot tables'!$O$3:$O$151,'pivot tables'!$P$3:$P$151),Table2[[#This Row],[Fertilizer(kg)]]) -> 728226.24 | P5: 1052.16 | Q5: =IF(Table2[[#This Row],[Pesticide(kg)]]="",_xlfn.XLOOKUP(Table2[[#This Row],[crop&state]],'pivot tables'!$O$3:$O$151,'pivot tables'!$Q$3:$Q$151),Table2[[#This Row],[Pesticide(kg)]]) -> 1052.16 | R5: 2.673 | S5: =IF(Table2[[#This Row],[Yield]]="",IFERROR(Table2[[#This Row],[Production(Tones)]]/Table2[[#This Row],[Area(hectare)]],""),Table2[[#This Row],[Yield]]) -> 2.673 | T5: 28.059 | U5: =IF(Table2[[#This Row],[Avg_Temperature(°C)]]="",IFERROR((Table2[[#This Row],[Max_Temperature(°C)]]+Table2[[#This Row],[Min_Temperature(°C)]])/2,""),Table2[[#This Row],[Avg_Temperature(°C)]]) -> 28.059 | V5: 32.519 | W5: =IF(Table2[[#This Row],[Max_Temperature(°C)]]="",_xlfn.XLOOKUP(Table2[[#This Row],[State]],'pivot tables'!$T$2:$T$33,'pivot tables'!$V$2:$V$33),Table2[[#This Row],[Max_Temperature(°C)]]) -> 32.519 | X5: 24.308 | Y5: =IF(Table2[[#This Row],[Min_Temperature(°C)]]="",_xlfn.XLOOKUP(Table2[[#This Row],[State]],'pivot tables'!$T$2:$T$33,'pivot tables'!$W$2:$W$33),Table2[[#This Row],[Min_Temperature(°C)]]) -> 24.308
A6: Rice | B6: 2010 | C6: Rabi | D6: =PROPER(TRIM(Table2[[#This Row],[Season]])) -> Rabi | E6: =IF(Table2[[#This Row],[Season]]="",_xlfn.XLOOKUP(Table2[[#This Row],[State]],'pivot tables'!$F$3:$F$33,'pivot tables'!$G$3:$G$33),Table2[[#This Row],[Season]]) -> Rabi | F6: Puducherry | G6: 10920 | H6: =IF(Table2[[#This Row],[Area(hectare)]]="",IFERROR(Table2[[#This Row],[Production(Tones)]]/Table2[[#This Row],[Yield blanks]],""),Table2[[#This Row],[Area(hectare)]]) -> 10920 | I6: 26585 | J6: =IF(Table2[[#This Row],[Production(Tones)]]="",Table2[[#This Row],[Area Blanks]]*Table2[[#This Row],[Yield]],Table2[[#This Row],[Production(Tones)]]) -> 26585 | K6: 1434.588 | L6: =IF(Table2[[#This Row],[Annual_Rainfall(mm)]]="",_xlfn.XLOOKUP(Table2[[#This Row],[State]],'pivot tables'!$J$3:$J$32,'pivot tables'!$K$3:$K$32),Table2[[#This Row],[Annual_Rainfall(mm)]]) -> 1434.588 | M6: =Table2[[#This Row],[Crop]]&Table2[[#This Row],[State]] -> RicePuducherry | N6: 1813921.2 | O6: =IF(Table2[[#This Row],[Fertilizer(kg)]]="",_xlfn.XLOOKUP(Table2[[#This Row],[crop&state]],'pivot tables'!$O$3:$O$151,'pivot tables'!$P$3:$P$151),Table2[[#This Row],[Fertilizer(kg)]]) -> 1813921.2 | P6: 2620.8 | Q6: =IF(Table2[[#This Row],[Pesticide(kg)]]="",_xlfn.XLOOKUP(Table2[[#This Row],[crop&state]],'pivot tables'!$O$3:$O$151,'pivot tables'!$Q$3:$Q$151),Table2[[#This Row],[Pesticide(kg)]]) -> 2620.8 | R6: 3.447 | S6: =IF(Table2[[#This Row],[Yield]]="",IFERROR(Table2[[#This Row],[Production(Tones)]]/Table2[[#This Row],[Area(hectare)]],""),Table2[[#This Row],[Yield]]) -> 3.447 | T6: 28.059 | U6: =IF(Table2[[#This Row],[Avg_Temperature(°C)]]="",IFERROR((Table2[[#This Row],[Max_Temperature(°C)]]+Table2[[#This Row],[Min_Temperature(°C)]])/2,""),Table2[[#This Row],[Avg_Temperature(°C)]]) -> 28.059 | V6: 32.519 | W6: =IF(Table2[[#This Row],[Max_Temperature(°C)]]="",_xlfn.XLOOKUP(Table2[[#This Row],[State]],'pivot tables'!$T$2:$T$33,'pivot tables'!$V$2:$V$33),Table2[[#This Row],[Max_Temperature(°C)]]) -> 32.519 | X6: 24.308 | Y6: =IF(Table2[[#This Row],[Min_Temperature(°C)]]="",_xlfn.XLOOKUP(Table2[[#This Row],[State]],'pivot tables'!$T$2:$T$33,'pivot tables'!$W$2:$W$33),Table2[[#This Row],[Min_Temperature(°C)]]) -> 24.308
A7: Rice | B7: 2010 | C7: Summer | D7: =PROPER(TRIM(Table2[[#This Row],[Season]])) -> Summer | E7: =IF(Table2[[#This Row],[Season]]="",_xlfn.XLOOKUP(Table2[[#This Row],[State]],'pivot tables'!$F$3:$F$33,'pivot tables'!$G$3:$G$33),Table2[[#This Row],[Season]]) -> Summer | F7: Puducherry | G7: 4710 | H7: =IF(Table2[[#This Row],[Area(hectare)]]="",IFERROR(Table2[[#This Row],[Production(Tones)]]/Table2[[#This Row],[Yield blanks]],""),Table2[[#This Row],[Area(hectare)]]) -> 4710 | I7: 12773 | J7: =IF(Table2[[#This Row],[Production(Tones)]]="",Table2[[#This Row],[Area Blanks]]*Table2[[#This Row],[Yield]],Table2[[#This Row],[Production(Tones)]]) -> 12773 | K7: 1434.588 | L7: =IF(Table2[[#This Row],[Annual_Rainfall(mm)]]="",_xlfn.XLOOKUP(Table2[[#This Row],[State]],'pivot tables'!$J$3:$J$32,'pivot tables'!$K$3:$K$32),Table2[[#This Row],[Annual_Rainfall(mm)]]) -> 1434.588 | M7: =Table2[[#This Row],[Crop]]&Table2[[#This Row],[State]] -> RicePuducherry | N7: 782378.1 | O7: =IF(Table2[[#This Row],[Fertilizer(kg)]]="",_xlfn.XLOOKUP(Table2[[#This Row],[crop&state]],'pivot tables'!$O$3:$O$151,'pivot tables'!$P$3:$P$151),Table2[[#This Row],[Fertilizer(kg)]]) -> 782378.1 | P7: 1130.4 | Q7: =IF(Table2[[#This Row],[Pesticide(kg)]]="",_xlfn.XLOOKUP(Table2[[#This Row],[crop&state]],'pivot tables'!$O$3:$O$151,'pivot tables'!$Q$3:$Q$151),Table2[[#This Row],[Pesticide(kg)]]) -> 1130.4 | R7: 2.7 | S7: =IF(Table2[[#This Row],[Yield]]="",IFERROR(Table2[[#This Row],[Production(Tones)]]/Table2[[#This Row],[Area(hectare)]],""),Table2[[#This Row],[Yield]]) -> 2.7 | T7: 28.059 | U7: =IF(Table2[[#This Row],[Avg_Temperature(°C)]]="",IFERROR((Table2[[#This Row],[Max_Temperature(°C)]]+Table2[[#This Row],[Min_Temperature(°C)]])/2,""),Table2[[#This Row],[Avg_Temperature(°C)]]) -> 28.059 | V7: 32.519 | W7: =IF(Table2[[#This Row],[Max_Temperature(°C)]]="",_xlfn.XLOOKUP(Table2[[#This Row],[State]],'pivot tables'!$T$2:$T$33,'pivot tables'!$V$2:$V$33),Table2[[#This Row],[Max_Temperature(°C)]]) -> 32.519 | X7: 24.308 | Y7: =IF(Table2[[#This Row],[Min_Temperature(°C)]]="",_xlfn.XLOOKUP(Table2[[#This Row],[State]],'pivot tables'!$T$2:$T$33,'pivot tables'!$W$2:$W$33),Table2[[#This Row],[Min_Temperature(°C)]]) -> 24.308
A8: Sugarcane | B8: 2010 | C8: Kharif | D8: =PROPER(TRIM(Table2[[#This Row],[Season]])) -> Kharif | E8: =IF(Table2[[#This Row],[Season]]="",_xlfn.XLOOKUP(Table2[[#This Row],[State]],'pivot tables'!$F$3:$F$33,'pivot tables'!$G$3:$G$33),Table2[[#This Row],[Season]]) -> Kharif | F8: Puducherry | G8: 1765 | H8: =IF(Table2[[#This Row],[Area(hectare)]]="",IFERROR(Table2[[#This Row],[Production(Tones)]]/Table2[[#This Row],[Yield blanks]],""),Table2[[#This Row],[Area(hectare)]]) -> 1765 | I8: 277683 | J8: =IF(Table2[[#This Row],[Production(Tones)]]="",Table2[[#This Row],[Area Blanks]]*Table2[[#This Row],[Yield]],Table2[[#This Row],[Production(Tones)]]) -> 277683 | K8: 1434.588 | L8: =IF(Table2[[#This Row],[Annual_Rainfall(mm)]]="",_xlfn.XLOOKUP(Table2[[#This Row],[State]],'pivot tables'!$J$3:$J$32,'pivot tables'!$K$3:$K$32),Table2[[#This Row],[Annual_Rainfall(mm)]]) -> 1434.588 | M8: =Table2[[#This Row],[Crop]]&Table2[[#This Row],[State]] -> SugarcanePuducherry | N8: 293184.15 | O8: =IF(Table2[[#This Row],[Fertilizer(kg)]]="",_xlfn.XLOOKUP(Table2[[#This Row],[crop&state]],'pivot tables'!$O$3:$O$151,'pivot tables'!$P$3:$P$151),Table2[[#This Row],[Fertilizer(kg)]]) -> 293184.15 | P8: 423.6 | Q8: =IF(Table2[[#This Row],[Pesticide(kg)]]="",_xlfn.XLOOKUP(Table2[[#This Row],[crop&state]],'pivot tables'!$O$3:$O$151,'pivot tables'!$Q$3:$Q$151),Table2[[#This Row],[Pesticide(kg)]]) -> 423.6 | R8: 115.19 | S8: =IF(Table2[[#This Row],[Yield]]="",IFERROR(Table2[[#This Row],[Production(Tones)]]/Table2[[#This Row],[Area(hectare)]],""),Table2[[#This Row],[Yield]]) -> 115.19 | T8: 28.059 | U8: =IF(Table2[[#This Row],[Avg_Temperature(°C)]]="",IFERROR((Table2[[#This Row],[Max_Temperature(°C)]]+Table2[[#This Row],[Min_Temperature(°C)]])/2,""),Table2[[#This Row],[Avg_Temperature(°C)]]) -> 28.059 | V8: 32.519 | W8: =IF(Table2[[#This Row],[Max_Temperature(°C)]]="",_xlfn.XLOOKUP(Table2[[#This Row],[State]],'pivot tables'!$T$2:$T$33,'pivot tables'!$V$2:$V$33),Table2[[#This Row],[Max_Temperature(°C)]]) -> 32.519 | X8: 24.308 | Y8: =IF(Table2[[#This Row],[Min_Temperature(°C)]]="",_xlfn.XLOOKUP(Table2[[#This Row],[State]],'pivot tables'!$T$2:$T$33,'pivot tables'!$W$2:$W$33),Table2[[#This Row],[Min_Temperature(°C)]]) -> 24.308
A9: Sunflower | B9: 2010 | C9: Kharif | D9: =PROPER(TRIM(Table2[[#This Row],[Season]])) -> Kharif | E9: =IF(Table2[[#This Row],[Season]]="",_xlfn.XLOOKUP(Table2[[#This Row],[State]],'pivot tables'!$F$3:$F$33,'pivot tables'!$G$3:$G$33),Table2[[#This Row],[Season]]) -> Kharif | F9: Puducherry | G9: 1 | H9: =IF(Table2[[#This Row],[Area(hectare)]]="",IFERROR(Table2[[#This Row],[Production(Tones)]]/Table2[[#This Row],[Yield blanks]],""),Table2[[#This Row],[Area(hectare)]]) -> 1 | I9: 1 | J9: =IF(Table2[[#This Row],[Production(Tones)]]="",Table2[[#This Row],[Area Blanks]]*Table2[[#This Row],[Yield]],Table2[[#This Row],[Production(Tones)]]) -> 1 | K9: 1434.588 | L9: =IF(Table2[[#This Row],[Annual_Rainfall(mm)]]="",_xlfn.XLOOKUP(Table2[[#This Row],[State]],'pivot tables'!$J$3:$J$32,'pivot tables'!$K$3:$K$32),Table2[[#This Row],[Annual_Rainfall(mm)]]) -> 1434.588 | M9: =Table2[[#This Row],[Crop]]&Table2[[#This Row],[State]] -> SunflowerPuducherry | N9: 166.11 | O9: =IF(Table2[[#This Row],[Fertilizer(kg)]]="",_xlfn.XLOOKUP(Table2[[#This Row],[crop&state]],'pivot tables'!$O$3:$O$151,'pivot tables'!$P$3:$P$151),Table2[[#This Row],[Fertilizer(kg)]]) -> 166.11 | P9: 0.24 | Q9: =IF(Table2[[#This Row],[Pesticide(kg)]]="",_xlfn.XLOOKUP(Table2[[#This Row],[crop&state]],'pivot tables'!$O$3:$O$151,'pivot tables'!$Q$3:$Q$151),Table2[[#This Row],[Pesticide(kg)]]) -> 0.24 | R9: 1 | S9: =IF(Table2[[#This Row],[Yield]]="",IFERROR(Table2[[#This Row],[Production(Tones)]]/Table2[[#This Row],[Area(hectare)]],""),Table2[[#This Row],[Yield]]) -> 1 | T9: 28.059 | U9: =IF(Table2[[#This Row],[Avg_Temperature(°C)]]="",IFERROR((Table2[[#This Row],[Max_Temperature(°C)]]+Table2[[#This Row],[Min_Temperature(°C)]])/2,""),Table2[[#This Row],[Avg_Temperature(°C)]]) -> 28.059 | V9: 32.519 | W9: =IF(Table2[[#This Row],[Max_Temperature(°C)]]="",_xlfn.XLOOKUP(Table2[[#This Row],[State]],'pivot tables'!$T$2:$T$33,'pivot tables'!$V$2:$V$33),Table2[[#This Row],[Max_Temperature(°C)]]) -> 32.519 | X9: 24.308 | Y9: =IF(Table2[[#This Row],[Min_Temperature(°C)]]="",_xlfn.XLOOKUP(Table2[[#This Row],[State]],'pivot tables'!$T$2:$T$33,'pivot tables'!$W$2:$W$33),Table2[[#This Row],[Min_Temperature(°C)]]) -> 24.308
A10: Urad | B10: 2010 | C10: Kharif | D10: =PROPER(TRIM(Table2[[#This Row],[Season]])) -> Kharif | E10: =IF(Table2[[#This Row],[Season]]="",_xlfn.XLOOKUP(Table2[[#This Row],[State]],'pivot tables'!$F$3:$F$33,'pivot tables'!$G$3:$G$33),Table2[[#This Row],[Season]]) -> Kharif | F10: Puducherry | G10: 22 | H10: =IF(Table2[[#This Row],[Area(hectare)]]="",IFERROR(Table2[[#This Row],[Production(Tones)]]/Table2[[#This Row],[Yield blanks]],""),Table2[[#This Row],[Area(hectare)]]) -> 22 | I10: 17 | J10: =IF(Table2[[#This Row],[Production(Tones)]]="",Table2[[#This Row],[Area Blanks]]*Table2[[#This Row],[Yield]],Table2[[#This Row],[Production(Tones)]]) -> 17 | K10: 1434.588 | L10: =IF(Table2[[#This Row],[Annual_Rainfall(mm)]]="",_xlfn.XLOOKUP(Table2[[#This Row],[State]],'pivot tables'!$J$3:$J$32,'pivot tables'!$K$3:$K$32),Table2[[#This Row],[Annual_Rainfall(mm)]]) -> 1434.588 | M10: =Table2[[#This Row],[Crop]]&Table2[[#This Row],[State]] -> UradPuducherry | N10: 3654.42 | O10: =IF(Table2[[#This Row],[Fertilizer(kg)]]="",_xlfn.XLOOKUP(Table2[[#This Row],[crop&state]],'pivot tables'!$O$3:$O$151,'pivot tables'!$P$3:$P$151),Table2[[#This Row],[Fertilizer(kg)]]) -> 3654.42 | P10: 5.28 | Q10: =IF(Table2[[#This Row],[Pesticide(kg)]]="",_xlfn.XLOOKUP(Table2[[#This Row],[crop&state]],'pivot tables'!$O$3:$O$151,'pivot tables'!$Q$3:$Q$151),Table2[[#This Row],[Pesticide(kg)]]) -> 5.28 | R10: 0.77 | S10: =IF(Table2[[#This Row],[Yield]]="",IFERROR(Table2[[#This Row],[Production(Tones)]]/Table2[[#This Row],[Area(hectare)]],""),Table2[[#This Row],[Yield]]) -> 0.77 | T10: 28.059 | U10: =IF(Table2[[#This Row],[Avg_Temperature(°C)]]="",IFERROR((Table2[[#This Row],[Max_Temperature(°C)]]+Table2[[#This Row],[Min_Temperature(°C)]])/2,""),Table2[[#This Row],[Avg_Temperature(°C)]]) -> 28.059 | V10: 32.519 | W10: =IF(Table2[[#This Row],[Max_Temperature(°C)]]="",_xlfn.XLOOKUP(Table2[[#This Row],[State]],'pivot tables'!$T$2:$T$33,'pivot tables'!$V$2:$V$33),Table2[[#This Row],[Max_Temperature(°C)]]) -> 32.519 | X10: 24.308 | Y10: =IF(Table2[[#This Row],[Min_Temperature(°C)]]="",_xlfn.XLOOKUP(Table2[[#This Row],[State]],'pivot tables'!$T$2:$T$33,'pivot tables'!$W$2:$W$33),Table2[[#This Row],[Min_Temperature(°C)]]) -> 24.308
A11: Urad | B11: 2010 | C11: Rabi | D11: =PROPER(TRIM(Table2[[#This Row],[Season]])) -> Rabi | E11: =IF(Table2[[#This Row],[Season]]="",_xlfn.XLOOKUP(Table2[[#This Row],[State]],'pivot tables'!$F$3:$F$33,'pivot tables'!$G$3:$G$33),Table2[[#This Row],[Season]]) -> Rabi | F11: Puducherry | G11: 189 | H11: =IF(Table2[[#This Row],[Area(hectare)]]="",IFERROR(Table2[[#This Row],[Production(Tones)]]/Table2[[#This Row],[Yield blanks]],""),Table2[[#This Row],[Area(hectare)]]) -> 189 | I11: 206 | J11: =IF(Table2[[#This Row],[Production(Tones)]]="",Table2[[#This Row],[Area Blanks]]*Table2[[#This Row],[Yield]],Table2[[#This Row],[Production(Tones)]]) -> 206 | K11: 1434.588 | L11: =IF(Table2[[#This Row],[Annual_Rainfall(mm)]]="",_xlfn.XLOOKUP(Table2[[#This Row],[State]],'pivot tables'!$J$3:$J$32,'pivot tables'!$K$3:$K$32),Table2[[#This Row],[Annual_Rainfall(mm)]]) -> 1434.588 | M11: =Table2[[#This Row],[Crop]]&Table2[[#This Row],[State]] -> UradPuducherry | N11: 31394.79 | O11: =IF(Table2[[#This Row],[Fertilizer(kg)]]="",_xlfn.XLOOKUP(Table2[[#This Row],[crop&state]],'pivot tables'!$O$3:$O$151,'pivot tables'!$P$3:$P$151),Table2[[#This Row],[Fertilizer(kg)]]) -> 31394.79 | P11: 45.36 | Q11: =IF(Table2[[#This Row],[Pesticide(kg)]]="",_xlfn.XLOOKUP(Table2[[#This Row],[crop&state]],'pivot tables'!$O$3:$O$151,'pivot tables'!$Q$3:$Q$151),Table2[[#This Row],[Pesticide(kg)]]) -> 45.36 | R11: 1.09 | S11: =IF(Table2[[#This Row],[Yield]]="",IFERROR(Table2[[#This Row],[Production(Tones)]]/Table2[[#This Row],[Area(hectare)]],""),Table2[[#This Row],[Yield]]) -> 1.09 | T11: 28.059 | U11: =IF(Table2[[#This Row],[Avg_Temperature(°C)]]="",IFERROR((Table2[[#This Row],[Max_Temperature(°C)]]+Table2[[#This Row],[Min_Temperature(°C)]])/2,""),Table2[[#This Row],[Avg_Temperature(°C)]]) -> 28.059 | V11: 32.519 | W11: =IF(Table2[[#This Row],[Max_Temperature(°C)]]="",_xlfn.XLOOKUP(Table2[[#This Row],[State]],'pivot tables'!$T$2:$T$33,'pivot tables'!$V$2:$V$33),Table2[[#This Row],[Max_Temperature(°C)]]) -> 32.519 | X11: 24.308 | Y11: =IF(Table2[[#This Row],[Min_Temperature(°C)]]="",_xlfn.XLOOKUP(Table2[[#This Row],[State]],'pivot tables'!$T$2:$T$33,'pivot tables'!$W$2:$W$33),Table2[[#This Row],[Min_Temperature(°C)]]) -> 24.308
A12: Urad | B12: 2010 | C12: Summer | D12: =PROPER(TRIM(Table2[[#This Row],[Season]])) -> Summer | E12: =IF(Table2[[#This Row],[Season]]="",_xlfn.XLOOKUP(Table2[[#This Row],[State]],'pivot tables'!$F$3:$F$33,'pivot tables'!$G$3:$G$33),Table2[[#This Row],[Season]]) -> Summer | F12: Puducherry | G12: 916 | H12: =IF(Table2[[#This Row],[Area(hectare)]]="",IFERROR(Table2[[#This Row],[Production(Tones)]]/Table2[[#This Row],[Yield blanks]],""),Table2[[#This Row],[Area(hectare)]]) -> 916 | I12: 374 | J12: =IF(Table2[[#This Row],[Production(Tones)]]="",Table2[[#This Row],[Area Blanks]]*Table2[[#This Row],[Yield]],Table2[[#This Row],[Production(Tones)]]) -> 374 | K12: 1434.588 | L12: =IF(Table2[[#This Row],[Annual_Rainfall(mm)]]="",_xlfn.XLOOKUP(Table2[[#This Row],[State]],'pivot tables'!$J$3:$J$32,'pivot tables'!$K$3:$K$32),Table2[[#This Row],[Annual_Rainfall(mm)]]) -> 1434.588 | M12: =Table2[[#This Row],[Crop]]&Table2[[#This Row],[State]] -> UradPuducherry | N12: 152156.76 | O12: =IF(Table2[[#This Row],[Fertilizer(kg)]]="",_xlfn.XLOOKUP(Table2[[#This Row],[crop&state]],'pivot tables'!$O$3:$O$151,'pivot tables'!$P$3:$P$151),Table2[[#This Row],[Fertilizer(kg)]]) -> 152156.76 | P12: 219.84 | Q12: =IF(Table2[[#This Row],[Pesticide(kg)]]="",_xlfn.XLOOKUP(Table2[[#This Row],[crop&state]],'pivot tables'!$O$3:$O$151,'pivot tables'!$Q$3:$Q$151),Table2[[#This Row],[Pesticide(kg)]]) -> 219.84 | R12: 0.627 | S12: =IF(Table2[[#This Row],[Yield]]="",IFERROR(Table2[[#This Row],[Production(Tones)]]/Table2[[#This Row],[Area(hectare)]],""),Table2[[#This Row],[Yield]]) -> 0.627 | T12: 28.059 | U12: =IF(Table2[[#This Row],[Avg_Temperature(°C)]]="",IFERROR((Table2[[#This Row],[Max_Temperature(°C)]]+Table2[[#This Row],[Min_Temperature(°C)]])/2,""),Table2[[#This Row],[Avg_Temperature(°C)]]) -> 28.059 | V12: 32.519 | W12: =IF(Table2[[#This Row],[Max_Temperature(°C)]]="",_xlfn.XLOOKUP(Table2[[#This Row],[State]],'pivot tables'!$T$2:$T$33,'pivot tables'!$V$2:$V$33),Table2[[#This Row],[Max_Temperature(°C)]]) -> 32.519 | X12: 24.308 | Y12: =IF(Table2[[#This Row],[Min_Temperature(°C)]]="",_xlfn.XLOOKUP(Table2[[#This Row],[State]],'pivot tables'!$T$2:$T$33,'pivot tables'!$W$2:$W$33),Table2[[#This Row],[Min_Temperature(°C)]]) -> 24.308
A13: Rice | B13: 2010 | C13: Autumn | D13: =PROPER(TRIM(Table2[[#This Row],[Season]])) -> Autumn | E13: =IF(Table2[[#This Row],[Season]]="",_xlfn.XLOOKUP(Table2[[#This Row],[State]],'pivot tables'!$F$3:$F$33,'pivot tables'!$G$3:$G$33),Table2[[#This Row],[Season]]) -> Autumn | F13: Assam | G13: 307988 | H13: =IF(Table2[[#This Row],[Area(hectare)]]="",IFERROR(Table2[[#This Row],[Production(Tones)]]/Table2[[#This Row],[Yield blanks]],""),Table2[[#This Row],[Area(hectare)]]) -> 307988 | I13: 355825 | J13: =IF(Table2[[#This Row],[Production(Tones)]]="",Table2[[#This Row],[Area Blanks]]*Table2[[#This Row],[Yield]],Table2[[#This Row],[Production(Tones)]]) -> 355825 | K13: 2578.5 | L13: =IF(Table2[[#This Row],[Annual_Rainfall(mm)]]="",_xlfn.XLOOKUP(Table2[[#This Row],[State]],'pivot tables'!$J$3:$J$32,'pivot tables'!$K$3:$K$32),Table2[[#This Row],[Annual_Rainfall(mm)]]) -> 2578.5 | M13: =Table2[[#This Row],[Crop]]&Table2[[#This Row],[State]] -> RiceAssam | N13: 51159887 | O13: =IF(Table2[[#This Row],[Fertilizer(kg)]]="",_xlfn.XLOOKUP(Table2[[#This Row],[crop&state]],'pivot tables'!$O$3:$O$151,'pivot tables'!$P$3:$P$151),Table2[[#This Row],[Fertilizer(kg)]]) -> 51159887 | P13: 73917.12 | Q13: =IF(Table2[[#This Row],[Pesticide(kg)]]="",_xlfn.XLOOKUP(Table2[[#This Row],[crop&state]],'pivot tables'!$O$3:$O$151,'pivot tables'!$Q$3:$Q$151),Table2[[#This Row],[Pesticide(kg)]]) -> 73917.12 | R13: 1.273 | S13: =IF(Table2[[#This Row],[Yield]]="",IFERROR(Table2[[#This Row],[Production(Tones)]]/Table2[[#This Row],[Area(hectare)]],""),Table2[[#This Row],[Yield]]) -> 1.273 | T13: 23.876 | U13: =IF(Table2[[#This Row],[Avg_Temperature(°C)]]="",IFERROR((Table2[[#This Row],[Max_Temperature(°C)]]+Table2[[#This Row],[Min_Temperature(°C)]])/2,""),Table2[[#This Row],[Avg_Temperature(°C)]]) -> 23.876 | V13: 32.111 | W13: =IF(Table2[[#This Row],[Max_Temperature(°C)]]="",_xlfn.XLOOKUP(Table2[[#This Row],[State]],'pivot tables'!$T$2:$T$33,'pivot tables'!$V$2:$V$33),Table2[[#This Row],[Max_Temperature(°C)]]) -> 32.111 | X13: 16.375 | Y13: =IF(Table2[[#This Row],[Min_Temperature(°C)]]="",_xlfn.XLOOKUP(Table2[[#This Row],[State]],'pivot tables'!$T$2:$T$33,'pivot tables'!$W$2:$W$33),Table2[[#This Row],[Min_Temperature(°C)]]) -> 16.375
A14: Rice | B14: 2010 | C14: Summer | D14: =PROPER(TRIM(Table2[[#This Row],[Season]])) -> Summer | E14: =IF(Table2[[#This Row],[Season]]="",_xlfn.XLOOKUP(Table2[[#This Row],[State]],'pivot tables'!$F$3:$F$33,'pivot tables'!$G$3:$G$33),Table2[[#This Row],[Season]]) -> Summer | F14: Assam | G14: 398785 | H14: =IF(Table2[[#This Row],[Area(hectare)]]="",IFERROR(Table2[[#This Row],[Production(Tones)]]/Table2[[#This Row],[Yield blanks]],""),Table2[[#This Row],[Area(hectare)]]) -> 398785 | I14: 1027575 | J14: =IF(Table2[[#This Row],[Production(Tones)]]="",Table2[[#This Row],[Area Blanks]]*Table2[[#This Row],[Yield]],Table2[[#This Row],[Production(Tones)]]) -> 1027575 | K14: 2578.5 | L14: =IF(Table2[[#This Row],[Annual_Rainfall(mm)]]="",_xlfn.XLOOKUP(Table2[[#This Row],[State]],'pivot tables'!$J$3:$J$32,'pivot tables'!$K$3:$K$32),Table2[[#This Row],[Annual_Rainfall(mm)]]) -> 2578.5 | M14: =Table2[[#This Row],[Crop]]&Table2[[#This Row],[State]] -> RiceAssam | N14: 66242176 | O14: =IF(Table2[[#This Row],[Fertilizer(kg)]]="",_xlfn.XLOOKUP(Table2[[#This Row],[crop&state]],'pivot tables'!$O$3:$O$151,'pivot tables'!$P$3:$P$151),Table2[[#This Row],[Fertilizer(kg)]]) -> 66242176 | P14: 95708.4 | Q14: =IF(Table2[[#This Row],[Pesticide(kg)]]="",_xlfn.XLOOKUP(Table2[[#This Row],[crop&state]],'pivot tables'!$O$3:$O$151,'pivot tables'!$Q$3:$Q$151),Table2[[#This Row],[Pesticide(kg)]]) -> 95708.4 | R14: 2.342 | S14: =IF(Table2[[#This Row],[Yield]]="",IFERROR(Table2[[#This Row],[Production(Tones)]]/Table2[[#This Row],[Area(hectare)]],""),Table2[[#This Row],[Yield]]) -> 2.342 | T14: 23.876 | U14: =IF(Table2[[#This Row],[Avg_Temperature(°C)]]="",IFERROR((Table2[[#This Row],[Max_Temperature(°C)]]+Table2[[#This Row],[Min_Temperature(°C)]])/2,""),Table2[[#This Row],[Avg_Temperature(°C)]]) -> 23.876 | V14: 32.111 | W14: =IF(Table2[[#This Row],[Max_Temperature(°C)]]="",_xlfn.XLOOKUP(Table2[[#This Row],[State]],'pivot tables'!$T$2:$T$33,'pivot tables'!$V$2:$V$33),Table2[[#This Row],[Max_Temperature(°C)]]) -> 32.111 | X14: 16.375 | Y14: =IF(Table2[[#This Row],[Min_Temperature(°C)]]="",_xlfn.XLOOKUP(Table2[[#This Row],[State]],'pivot tables'!$T$2:$T$33,'pivot tables'!$W$2:$W$33),Table2[[#This Row],[Min_Temperature(°C)]]) -> 16.375
A15: Rice | B15: 2010 | C15: Winter | D15: =PROPER(TRIM(Table2[[#This Row],[Season]])) -> Winter | E15: =IF(Table2[[#This Row],[Season]]="",_xlfn.XLOOKUP(Table2[[#This Row],[State]],'pivot tables'!$F$3:$F$33,'pivot tables'!$G$3:$G$33),Table2[[#This Row],[Season]]) -> Winter | F15: Assam | G15: 1830682 | H15: =IF(Table2[[#This Row],[Area(hectare)]]="",IFERROR(Table2[[#This Row],[Production(Tones)]]/Table2[[#This Row],[Yield blanks]],""),Table2[[#This Row],[Area(hectare)]]) -> 1830682 | I15: 3649129 | J15: =IF(Table2[[#This Row],[Production(Tones)]]="",Table2[[#This Row],[Area Blanks]]*Table2[[#This Row],[Yield]],Table2[[#This Row],[Production(Tones)]]) -> 3649129 | K15: 2578.5 | L15: =IF(Table2[[#This Row],[Annual_Rainfall(mm)]]="",_xlfn.XLOOKUP(Table2[[#This Row],[State]],'pivot tables'!$J$3:$J$32,'pivot tables'!$K$3:$K$32),Table2[[#This Row],[Annual_Rainfall(mm)]]) -> 2578.5 | M15: =Table2[[#This Row],[Crop]]&Table2[[#This Row],[State]] -> RiceAssam | N15: 304094587 | O15: =IF(Table2[[#This Row],[Fertilizer(kg)]]="",_xlfn.XLOOKUP(Table2[[#This Row],[crop&state]],'pivot tables'!$O$3:$O$151,'pivot tables'!$P$3:$P$151),Table2[[#This Row],[Fertilizer(kg)]]) -> 304094587 | P15: 439363.68 | Q15: =IF(Table2[[#This Row],[Pesticide(kg)]]="",_xlfn.XLOOKUP(Table2[[#This Row],[crop&state]],'pivot tables'!$O$3:$O$151,'pivot tables'!$Q$3:$Q$151),Table2[[#This Row],[Pesticide(kg)]]) -> 439363.68 | R15: 1.959 | S15: =IF(Table2[[#This Row],[Yield]]="",IFERROR(Table2[[#This Row],[Production(Tones)]]/Table2[[#This Row],[Area(hectare)]],""),Table2[[#This Row],[Yield]]) -> 1.959 | T15: 23.876 | U15: =IF(Table2[[#This Row],[Avg_Temperature(°C)]]="",IFERROR((Table2[[#This Row],[Max_Temperature(°C)]]+Table2[[#This Row],[Min_Temperature(°C)]])/2,""),Table2[[#This Row],[Avg_Temperature(°C)]]) -> 23.876 | V15: 32.111 | W15: =IF(Table2[[#This Row],[Max_Temperature(°C)]]="",_xlfn.XLOOKUP(Table2[[#This Row],[State]],'pivot tables'!$T$2:$T$33,'pivot tables'!$V$2:$V$33),Table2[[#This Row],[Max_Temperature(°C)]]) -> 32.111 | X15: 16.375 | Y15: =IF(Table2[[#This Row],[Min_Temperature(°C)]]="",_xlfn.XLOOKUP(Table2[[#This Row],[State]],'pivot tables'!$T$2:$T$33,'pivot tables'!$W$2:$W$33),Table2[[#This Row],[Min_Temperature(°C)]]) -> 16.375
... A21: Rice | B21: 2010 | C21: Kharif | D21: =PROPER(TRIM(Table2[[#This Row],[Season]])) -> Kharif | E21: =IF(Table2[[#This Row],[Season]]="",_xlfn.XLOOKUP(Table2[[#This Row],[State]],'pivot tables'!$F$3:$F$33,'pivot tables'!$G$3:$G$33),Table2[[#This Row],[Season]]) -> Kharif | F21: Andhra Pradesh | G21: 2921793 | H21: =IF(Table2[[#This Row],[Area(hectare)]]="",IFERROR(Table2[[#This Row],[Production(Tones)]]/Table2[[#This Row],[Yield blanks]],""),Table2[[#This Row],[Area(hectare)]]) -> 2921793 | I21: -7509866 | J21: =IF(Table2[[#This Row],[Production(Tones)]]="",Table2[[#This Row],[Area Blanks]]*Table2[[#This Row],[Yield]],Table2[[#This Row],[Production(Tones)]]) -> -7509866 | K21: 1297 | L21: =IF(Table2[[#This Row],[Annual_Rainfall(mm)]]="",_xlfn.XLOOKUP(Table2[[#This Row],[State]],'pivot tables'!$J$3:$J$32,'pivot tables'!$K$3:$K$32),Table2[[#This Row],[Annual_Rainfall(mm)]]) -> 1297 | M21: =Table2[[#This Row],[Crop]]&Table2[[#This Row],[State]] -> RiceAndhra Pradesh | N21: 4.8533904e+08 | O21: =IF(Table2[[#This Row],[Fertilizer(kg)]]="",_xlfn.XLOOKUP(Table2[[#This Row],[crop&state]],'pivot tables'!$O$3:$O$151,'pivot tables'!$P$3:$P$151),Table2[[#This Row],[Fertilizer(kg)]]) -> 4.8533904e+08 | P21: 701230.32 | Q21: =IF(Table2[[#This Row],[Pesticide(kg)]]="",_xlfn.XLOOKUP(Table2[[#This Row],[crop&state]],'pivot tables'!$O$3:$O$151,'pivot tables'!$Q$3:$Q$151),Table2[[#This Row],[Pesticide(kg)]]) -> 701230.32 | R21: 2.667 | S21: =IF(Table2[[#This Row],[Yield]]="",IFERROR(Table2[[#This Row],[Production(Tones)]]/Table2[[#This Row],[Area(hectare)]],""),Table2[[#This Row],[Yield]]) -> 2.667 | T21: 27.928 | U21: =IF(Table2[[#This Row],[Avg_Temperature(°C)]]="",IFERROR((Table2[[#This Row],[Max_Temperature(°C)]]+Table2[[#This Row],[Min_Temperature(°C)]])/2,""),Table2[[#This Row],[Avg_Temperature(°C)]]) -> 27.928 | V21: 37.308 | W21: =IF(Table2[[#This Row],[Max_Temperature(°C)]]="",_xlfn.XLOOKUP(Table2[[#This Row],[State]],'pivot tables'!$T$2:$T$33,'pivot tables'!$V$2:$V$33),Table2[[#This Row],[Max_Temperature(°C)]]) -> 37.308 | X21: 20.51 | Y21: =IF(Table2[[#This Row],[Min_Temperature(°C)]]="",_xlfn.XLOOKUP(Table2[[#This Row],[State]],'pivot tables'!$T$2:$T$33,'pivot tables'!$W$2:$W$33),Table2[[#This Row],[Min_Temperature(°C)]]) -> 20.51
A22: Rice | B22: 2010 | C22: Rabi | D22: =PROPER(TRIM(Table2[[#This Row],[Season]])) -> Rabi | E22: =IF(Table2[[#This Row],[Season]]="",_xlfn.XLOOKUP(Table2[[#This Row],[State]],'pivot tables'!$F$3:$F$33,'pivot tables'!$G$3:$G$33),Table2[[#This Row],[Season]]) -> Rabi | F22: Andhra Pradesh | G22: 1829516 | H22: =IF(Table2[[#This Row],[Area(hectare)]]="",IFERROR(Table2[[#This Row],[Production(Tones)]]/Table2[[#This Row],[Yield blanks]],""),Table2[[#This Row],[Area(hectare)]]) -> 1829516 | I22: 6909447 | J22: =IF(Table2[[#This Row],[Production(Tones)]]="",Table2[[#This Row],[Area Blanks]]*Table2[[#This Row],[Yield]],Table2[[#This Row],[Production(Tones)]]) -> 6909447 | L22: =IF(Table2[[#This Row],[Annual_Rainfall(mm)]]="",_xlfn.XLOOKUP(Table2[[#This Row],[State]],'pivot tables'!$J$3:$J$32,'pivot tables'!$K$3:$K$32),Table2[[#This Row],[Annual_Rainfall(mm)]]) -> 956.04894 | M22: =Table2[[#This Row],[Crop]]&Table2[[#This Row],[State]] -> RiceAndhra Pradesh | N22: 3.039009e+08 | O22: =IF(Table2[[#This Row],[Fertilizer(kg)]]="",_xlfn.XLOOKUP(Table2[[#This Row],[crop&state]],'pivot tables'!$O$3:$O$151,'pivot tables'!$P$3:$P$151),Table2[[#This Row],[Fertilizer(kg)]]) -> 3.039009e+08 | P22: 439083.84 | Q22: =IF(Table2[[#This Row],[Pesticide(kg)]]="",_xlfn.XLOOKUP(Table2[[#This Row],[crop&state]],'pivot tables'!$O$3:$O$151,'pivot tables'!$Q$3:$Q$151),Table2[[#This Row],[Pesticide(kg)]]) -> 439083.84 | R22: 3.326 | S22: =IF(Table2[[#This Row],[Yield]]="",IFERROR(Table2[[#This Row],[Production(Tones)]]/Table2[[#This Row],[Area(hectare)]],""),Table2[[#This Row],[Yield]]) -> 3.326 | U22: =IF(Table2[[#This Row],[Avg_Temperature(°C)]]="",IFERROR((Table2[[#This Row],[Max_Temperature(°C)]]+Table2[[#This Row],[Min_Temperature(°C)]])/2,""),Table2[[#This Row],[Avg_Temperature(°C)]]) -> 28.909 | V22: 37.308 | W22: =IF(Table2[[#This Row],[Max_Temperature(°C)]]="",_xlfn.XLOOKUP(Table2[[#This Row],[State]],'pivot tables'!$T$2:$T$33,'pivot tables'!$V$2:$V$33),Table2[[#This Row],[Max_Temperature(°C)]]) -> 37.308 | X22: 20.51 | Y22: =IF(Table2[[#This Row],[Min_Temperature(°C)]]="",_xlfn.XLOOKUP(Table2[[#This Row],[State]],'pivot tables'!$T$2:$T$33,'pivot tables'!$W$2:$W$33),Table2[[#This Row],[Min_Temperature(°C)]]) -> 20.51
A23: Sugarcane | B23: 2010 | C23: Whole Year | D23: =PROPER(TRIM(Table2[[#This Row],[Season]])) -> Whole Year | E23: =IF(Table2[[#This Row],[Season]]="",_xlfn.XLOOKUP(Table2[[#This Row],[State]],'pivot tables'!$F$3:$F$33,'pivot tables'!$G$3:$G$33),Table2[[#This Row],[Season]]) -> Whole Year | F23: Andhra Pradesh | G23: 191729 | H23: =IF(Table2[[#This Row],[Area(hectare)]]="",IFERROR(Table2[[#This Row],[Production(Tones)]]/Table2[[#This Row],[Yield blanks]],""),Table2[[#This Row],[Area(hectare)]]) -> 191729 | I23: 14942455 | J23: =IF(Table2[[#This Row],[Production(Tones)]]="",Table2[[#This Row],[Area Blanks]]*Table2[[#This Row],[Yield]],Table2[[#This Row],[Production(Tones)]]) -> 14942455 | K23: 1297 | L23: =IF(Table2[[#This Row],[Annual_Rainfall(mm)]]="",_xlfn.XLOOKUP(Table2[[#This Row],[State]],'pivot tables'!$J$3:$J$32,'pivot tables'!$K$3:$K$32),Table2[[#This Row],[Annual_Rainfall(mm)]]) -> 1297 | M23: =Table2[[#This Row],[Crop]]&Table2[[#This Row],[State]] -> SugarcaneAndhra Pradesh | N23: 31848104 | O23: =IF(Table2[[#This Row],[Fertilizer(kg)]]="",_xlfn.XLOOKUP(Table2[[#This Row],[crop&state]],'pivot tables'!$O$3:$O$151,'pivot tables'!$P$3:$P$151),Table2[[#This Row],[Fertilizer(kg)]]) -> 31848104 | P23: 46014.96 | Q23: =IF(Table2[[#This Row],[Pesticide(kg)]]="",_xlfn.XLOOKUP(Table2[[#This Row],[crop&state]],'pivot tables'!$O$3:$O$151,'pivot tables'!$Q$3:$Q$151),Table2[[#This Row],[Pesticide(kg)]]) -> 46014.96 | R23: 81.584 | S23: =IF(Table2[[#This Row],[Yield]]="",IFERROR(Table2[[#This Row],[Production(Tones)]]/Table2[[#This Row],[Area(hectare)]],""),Table2[[#This Row],[Yield]]) -> 81.584 | T23: 27.928 | U23: =IF(Table2[[#This Row],[Avg_Temperature(°C)]]="",IFERROR((Table2[[#This Row],[Max_Temperature(°C)]]+Table2[[#This Row],[Min_Temperature(°C)]])/2,""),Table2[[#This Row],[Avg_Temperature(°C)]]) -> 27.928 | V23: 37.308 | W23: =IF(Table2[[#This Row],[Max_Temperature(°C)]]="",_xlfn.XLOOKUP(Table2[[#This Row],[State]],'pivot tables'!$T$2:$T$33,'pivot tables'!$V$2:$V$33),Table2[[#This Row],[Max_Temperature(°C)]]) -> 37.308 | X23: 20.51 | Y23: =IF(Table2[[#This Row],[Min_Temperature(°C)]]="",_xlfn.XLOOKUP(Table2[[#This Row],[State]],'pivot tables'!$T$2:$T$33,'pivot tables'!$W$2:$W$33),Table2[[#This Row],[Min_Temperature(°C)]]) -> 20.51
A24: Sunflower | B24: 2010 | C24: Whole Year | D24: =PROPER(TRIM(Table2[[#This Row],[Season]])) -> Whole Year | E24: =IF(Table2[[#This Row],[Season]]="",_xlfn.XLOOKUP(Table2[[#This Row],[State]],'pivot tables'!$F$3:$F$33,'pivot tables'!$G$3:$G$33),Table2[[#This Row],[Season]]) -> Whole Year | F24: Andhra Pradesh | G24: 225361 | H24: =IF(Table2[[#This Row],[Area(hectare)]]="",IFERROR(Table2[[#This Row],[Production(Tones)]]/Table2[[#This Row],[Yield blanks]],""),Table2[[#This Row],[Area(hectare)]]) -> 225361 | I24: 156170 | J24: =IF(Table2[[#This Row],[Production(Tones)]]="",Table2[[#This Row],[Area Blanks]]*Table2[[#This Row],[Yield]],Table2[[#This Row],[Production(Tones)]]) -> 156170 | K24: 1297 | L24: =IF(Table2[[#This Row],[Annual_Rainfall(mm)]]="",_xlfn.XLOOKUP(Table2[[#This Row],[State]],'pivot tables'!$J$3:$J$32,'pivot tables'!$K$3:$K$32),Table2[[#This Row],[Annual_Rainfall(mm)]]) -> 1297 | M24: =Table2[[#This Row],[Crop]]&Table2[[#This Row],[State]] -> SunflowerAndhra Pradesh | N24: 37434716 | O24: =IF(Table2[[#This Row],[Fertilizer(kg)]]="",_xlfn.XLOOKUP(Table2[[#This Row],[crop&state]],'pivot tables'!$O$3:$O$151,'pivot tables'!$P$3:$P$151),Table2[[#This Row],[Fertilizer(kg)]]) -> 37434716 | Q24: =IF(Table2[[#This Row],[Pesticide(kg)]]="",_xlfn.XLOOKUP(Table2[[#This Row],[crop&state]],'pivot tables'!$O$3:$O$151,'pivot tables'!$Q$3:$Q$151),Table2[[#This Row],[Pesticide(kg)]]) -> 9934.5656 | R24: 1.032 | S24: =IF(Table2[[#This Row],[Yield]]="",IFERROR(Table2[[#This Row],[Production(Tones)]]/Table2[[#This Row],[Area(hectare)]],""),Table2[[#This Row],[Yield]]) -> 1.032 | T24: 27.928 | U24: =IF(Table2[[#This Row],[Avg_Temperature(°C)]]="",IFERROR((Table2[[#This Row],[Max_Temperature(°C)]]+Table2[[#This Row],[Min_Temperature(°C)]])/2,""),Table2[[#This Row],[Avg_Temperature(°C)]]) -> 27.928 | V24: 37.308 | W24: =IF(Table2[[#This Row],[Max_Temperature(°C)]]="",_xlfn.XLOOKUP(Table2[[#This Row],[State]],'pivot tables'!$T$2:$T$33,'pivot tables'!$V$2:$V$33),Table2[[#This Row],[Max_Temperature(°C)]]) -> 37.308 | X24: 20.51 | Y24: =IF(Table2[[#This Row],[Min_Temperature(°C)]]="",_xlfn.XLOOKUP(Table2[[#This Row],[State]],'pivot tables'!$T$2:$T$33,'pivot tables'!$W$2:$W$33),Table2[[#This Row],[Min_Temperature(°C)]]) -> 20.51
A25: Urad | B25: 2010 | C25: Kharif | D25: =PROPER(TRIM(Table2[[#This Row],[Season]])) -> Kharif | E25: =IF(Table2[[#This Row],[Season]]="",_xlfn.XLOOKUP(Table2[[#This Row],[State]],'pivot tables'!$F$3:$F$33,'pivot tables'!$G$3:$G$33),Table2[[#This Row],[Season]]) -> Kharif | F25: Andhra Pradesh | G25: 82317 | H25: =IF(Table2[[#This Row],[Area(hectare)]]="",IFERROR(Table2[[#This Row],[Production(Tones)]]/Table2[[#This Row],[Yield blanks]],""),Table2[[#This Row],[Area(hectare)]]) -> 82317 | I25: 46191 | J25: =IF(Table2[[#This Row],[Production(Tones)]]="",Table2[[#This Row],[Area Blanks]]*Table2[[#This Row],[Yield]],Table2[[#This Row],[Production(Tones)]]) -> 46191 | K25: 1297 | L25: =IF(Table2[[#This Row],[Annual_Rainfall(mm)]]="",_xlfn.XLOOKUP(Table2[[#This Row],[State]],'pivot tables'!$J$3:$J$32,'pivot tables'!$K$3:$K$32),Table2[[#This Row],[Annual_Rainfall(mm)]]) -> 1297 | M25: =Table2[[#This Row],[Crop]]&Table2[[#This Row],[State]] -> UradAndhra Pradesh | N25: 13673677 | O25: =IF(Table2[[#This Row],[Fertilizer(kg)]]="",_xlfn.XLOOKUP(Table2[[#This Row],[crop&state]],'pivot tables'!$O$3:$O$151,'pivot tables'!$P$3:$P$151),Table2[[#This Row],[Fertilizer(kg)]]) -> 13673677 | P25: 19756.08 | Q25: =IF(Table2[[#This Row],[Pesticide(kg)]]="",_xlfn.XLOOKUP(Table2[[#This Row],[crop&state]],'pivot tables'!$O$3:$O$151,'pivot tables'!$Q$3:$Q$151),Table2[[#This Row],[Pesticide(kg)]]) -> 19756.08 | R25: 0.473 | S25: =IF(Table2[[#This Row],[Yield]]="",IFERROR(Table2[[#This Row],[Production(Tones)]]/Table2[[#This Row],[Area(hectare)]],""),Table2[[#This Row],[Yield]]) -> 0.473 | T25: 27.928 | U25: =IF(Table2[[#This Row],[Avg_Temperature(°C)]]="",IFERROR((Table2[[#This Row],[Max_Temperature(°C)]]+Table2[[#This Row],[Min_Temperature(°C)]])/2,""),Table2[[#This Row],[Avg_Temperature(°C)]]) -> 27.928 | V25: 37.308 | W25: =IF(Table2[[#This Row],[Max_Temperature(°C)]]="",_xlfn.XLOOKUP(Table2[[#This Row],[State]],'pivot tables'!$T$2:$T$33,'pivot tables'!$V$2:$V$33),Table2[[#This Row],[Max_Temperature(°C)]]) -> 37.308 | X25: 20.51 | Y25: =IF(Table2[[#This Row],[Min_Temperature(°C)]]="",_xlfn.XLOOKUP(Table2[[#This Row],[State]],'pivot tables'!$T$2:$T$33,'pivot tables'!$W$2:$W$33),Table2[[#This Row],[Min_Temperature(°C)]]) -> 20.51
A26: Urad | B26: 2010 | C26: Rabi | D26: =PROPER(TRIM(Table2[[#This Row],[Season]])) -> Rabi | E26: =IF(Table2[[#This Row],[Season]]="",_xlfn.XLOOKUP(Table2[[#This Row],[State]],'pivot tables'!$F$3:$F$33,'pivot tables'!$G$3:$G$33),Table2[[#This Row],[Season]]) -> Rabi | F26: Andhra Pradesh | G26: 381529 | H26: =IF(Table2[[#This Row],[Area(hectare)]]="",IFERROR(Table2[[#This Row],[Production(Tones)]]/Table2[[#This Row],[Yield blanks]],""),Table2[[#This Row],[Area(hectare)]]) -> 381529 | I26: 207272 | J26: =IF(Table2[[#This Row],[Production(Tones)]]="",Table2[[#This Row],[Area Blanks]]*Table2[[#This Row],[Yield]],Table2[[#This Row],[Production(Tones)]]) -> 207272 | K26: 1297 | L26: =IF(Table2[[#This Row],[Annual_Rainfall(mm)]]="",_xlfn.XLOOKUP(Table2[[#This Row],[State]],'pivot tables'!$J$3:$J$32,'pivot tables'!$K$3:$K$32),Table2[[#This Row],[Annual_Rainfall(mm)]]) -> 1297 | M26: =Table2[[#This Row],[Crop]]&Table2[[#This Row],[State]] -> UradAndhra Pradesh | N26: 63375782 | O26: =IF(Table2[[#This Row],[Fertilizer(kg)]]="",_xlfn.XLOOKUP(Table2[[#This Row],[crop&state]],'pivot tables'!$O$3:$O$151,'pivot tables'!$P$3:$P$151),Table2[[#This Row],[Fertilizer(kg)]]) -> 63375782 | P26: 91566.96 | Q26: =IF(Table2[[#This Row],[Pesticide(kg)]]="",_xlfn.XLOOKUP(Table2[[#This Row],[crop&state]],'pivot tables'!$O$3:$O$151,'pivot tables'!$Q$3:$Q$151),Table2[[#This Row],[Pesticide(kg)]]) -> 91566.96 | R26: 0.574 | S26: =IF(Table2[[#This Row],[Yield]]="",IFERROR(Table2[[#This Row],[Production(Tones)]]/Table2[[#This Row],[Area(hectare)]],""),Table2[[#This Row],[Yield]]) -> 0.574 | T26: 27.928 | U26: =IF(Table2[[#This Row],[Avg_Temperature(°C)]]="",IFERROR((Table2[[#This Row],[Max_Temperature(°C)]]+Table2[[#This Row],[Min_Temperature(°C)]])/2,""),Table2[[#This Row],[Avg_Temperature(°C)]]) -> 27.928 | V26: 37.308 | W26: =IF(Table2[[#This Row],[Max_Temperature(°C)]]="",_xlfn.XLOOKUP(Table2[[#This Row],[State]],'pivot tables'!$T$2:$T$33,'pivot tables'!$V$2:$V$33),Table2[[#This Row],[Max_Temperature(°C)]]) -> 37.308 | X26: 20.51 | Y26: =IF(Table2[[#This Row],[Min_Temperature(°C)]]="",_xlfn.XLOOKUP(Table2[[#This Row],[State]],'pivot tables'!$T$2:$T$33,'pivot tables'!$W$2:$W$33),Table2[[#This Row],[Min_Temperature(°C)]]) -> 20.51
